/Users/temanmarket/.pyenv/versions/3.9.7/lib/python3.9/site-packages/rasa/core/tracker_store.py:1044: MovedIn20Warning: Deprecated API features detected! These feature(s) are not compatible with SQLAlchemy 2.0. To prevent incompatible upgrades prior to updating applications, ensure requirements files are pinned to "sqlalchemy<2.0". Set environment variable SQLALCHEMY_WARN_20=1 to show all deprecation warnings.  Set environment variable SQLALCHEMY_SILENCE_UBER_WARNING=1 to silence this message. (Background on SQLAlchemy 2.0 at: https://sqlalche.me/e/b8d9)
  Base: DeclarativeMeta = declarative_base()
/Users/temanmarket/.pyenv/versions/3.9.7/lib/python3.9/site-packages/rasa/shared/utils/validation.py:134: DeprecationWarning: pkg_resources is deprecated as an API. See https://setuptools.pypa.io/en/latest/pkg_resources.html
  import pkg_resources
/Users/temanmarket/.pyenv/versions/3.9.7/lib/python3.9/site-packages/pkg_resources/__init__.py:3117: DeprecationWarning: Deprecated call to `pkg_resources.declare_namespace('mpl_toolkits')`.
Implementing implicit namespace packages (as specified in PEP 420) is preferred to `pkg_resources.declare_namespace`. See https://setuptools.pypa.io/en/latest/references/keywords.html#keyword-namespace-packages
  declare_namespace(pkg)
/Users/temanmarket/.pyenv/versions/3.9.7/lib/python3.9/site-packages/pkg_resources/__init__.py:3117: DeprecationWarning: Deprecated call to `pkg_resources.declare_namespace('ruamel')`.
Implementing implicit namespace packages (as specified in PEP 420) is preferred to `pkg_resources.declare_namespace`. See https://setuptools.pypa.io/en/latest/references/keywords.html#keyword-namespace-packages
  declare_namespace(pkg)
/Users/temanmarket/.pyenv/versions/3.9.7/lib/python3.9/site-packages/sanic_cors/extension.py:39: DeprecationWarning: distutils Version classes are deprecated. Use packaging.version instead.
  SANIC_VERSION = LooseVersion(sanic_version)
/Users/temanmarket/.pyenv/versions/3.9.7/lib/python3.9/site-packages/tensorflow/lite/python/util.py:52: DeprecationWarning: jax.xla_computation is deprecated. Please use the AOT APIs.
  from jax import xla_computation as _xla_computation
2025-06-06 18:46:33 INFO     root  - Starting Rasa server on http://0.0.0.0:5005
2025-06-06 18:46:34 INFO     rasa.core.processor  - Loading model models/20250606-184317-pale-tab.tar.gz...
[93m/Users/temanmarket/.pyenv/versions/3.9.7/lib/python3.9/site-packages/rasa/shared/utils/io.py:99: UserWarning: Failed to load RegexEntityExtractor from model storage. This can happen if the model could not be trained because regexes could not be extracted from the given training data - and hence could not be persisted.
[0m[93m/Users/temanmarket/.pyenv/versions/3.9.7/lib/python3.9/site-packages/rasa/utils/train_utils.py:530: UserWarning: constrain_similarities is set to `False`. It is recommended to set it to `True` when using cross-entropy loss.
  rasa.shared.utils.io.raise_warning(
[0m2025-06-06 18:49:54 INFO     root  - Rasa server is up and running.
[93m/Users/temanmarket/.pyenv/versions/3.9.7/lib/python3.9/site-packages/rasa/shared/utils/io.py:99: UserWarning: The RegexEntityExtractor has not been trained properly yet. Continuing without extracting entities via this extractor.
[0m2025-06-07 00:55:33 ERROR    rasa.core.actions.action  - Failed to run custom action 'action_handle_chatbot'. Couldn't connect to the server at 'http://localhost:5055/webhook'. Is the server running? Error: Cannot connect to host localhost:5055 ssl:default [Connection refused]
2025-06-07 00:55:33 ERROR    rasa.core.processor  - Encountered an exception while running action 'action_handle_chatbot'.Bot will continue, but the actions events are lost. Please check the logs of your action server for more information.
Traceback (most recent call last):
  File "/Users/temanmarket/.pyenv/versions/3.9.7/lib/python3.9/site-packages/aiohttp/connector.py", line 1025, in _wrap_create_connection
    return await self._loop.create_connection(*args, **kwargs)
  File "uvloop/loop.pyx", line 2043, in create_connection
  File "uvloop/loop.pyx", line 2020, in uvloop.loop.Loop.create_connection
ConnectionRefusedError: [Errno 61] Connection refused

The above exception was the direct cause of the following exception:

Traceback (most recent call last):
  File "/Users/temanmarket/.pyenv/versions/3.9.7/lib/python3.9/site-packages/rasa/core/actions/action.py", line 780, in run
    response: Any = await self.action_endpoint.request(
  File "/Users/temanmarket/.pyenv/versions/3.9.7/lib/python3.9/site-packages/rasa/utils/endpoints.py", line 174, in request
    async with session.request(
  File "/Users/temanmarket/.pyenv/versions/3.9.7/lib/python3.9/site-packages/aiohttp/client.py", line 1197, in __aenter__
    self._resp = await self._coro
  File "/Users/temanmarket/.pyenv/versions/3.9.7/lib/python3.9/site-packages/aiohttp/client.py", line 581, in _request
    conn = await self._connector.connect(
  File "/Users/temanmarket/.pyenv/versions/3.9.7/lib/python3.9/site-packages/aiohttp/connector.py", line 544, in connect
    proto = await self._create_connection(req, traces, timeout)
  File "/Users/temanmarket/.pyenv/versions/3.9.7/lib/python3.9/site-packages/aiohttp/connector.py", line 944, in _create_connection
    _, proto = await self._create_direct_connection(req, traces, timeout)
  File "/Users/temanmarket/.pyenv/versions/3.9.7/lib/python3.9/site-packages/aiohttp/connector.py", line 1257, in _create_direct_connection
    raise last_exc
  File "/Users/temanmarket/.pyenv/versions/3.9.7/lib/python3.9/site-packages/aiohttp/connector.py", line 1226, in _create_direct_connection
    transp, proto = await self._wrap_create_connection(
  File "/Users/temanmarket/.pyenv/versions/3.9.7/lib/python3.9/site-packages/aiohttp/connector.py", line 1033, in _wrap_create_connection
    raise client_error(req.connection_key, exc) from exc
aiohttp.client_exceptions.ClientConnectorError: Cannot connect to host localhost:5055 ssl:default [Connection refused]

During handling of the above exception, another exception occurred:

Traceback (most recent call last):
  File "/Users/temanmarket/.pyenv/versions/3.9.7/lib/python3.9/site-packages/rasa/core/processor.py", line 982, in _run_action
    events = await action.run(
  File "/Users/temanmarket/.pyenv/versions/3.9.7/lib/python3.9/site-packages/rasa/core/actions/action.py", line 821, in run
    raise RasaException(
rasa.shared.exceptions.RasaException: Failed to execute custom action 'action_handle_chatbot'. Couldn't connect to the server at 'http://localhost:5055/webhook.
2025-06-07 00:56:14 ERROR    rasa.core.actions.action  - Failed to run custom action 'action_handle_chatbot'. Couldn't connect to the server at 'http://localhost:5055/webhook'. Is the server running? Error: Cannot connect to host localhost:5055 ssl:default [Connection refused]
2025-06-07 00:56:14 ERROR    rasa.core.processor  - Encountered an exception while running action 'action_handle_chatbot'.Bot will continue, but the actions events are lost. Please check the logs of your action server for more information.
Traceback (most recent call last):
  File "/Users/temanmarket/.pyenv/versions/3.9.7/lib/python3.9/site-packages/aiohttp/connector.py", line 1025, in _wrap_create_connection
    return await self._loop.create_connection(*args, **kwargs)
  File "uvloop/loop.pyx", line 2043, in create_connection
  File "uvloop/loop.pyx", line 2020, in uvloop.loop.Loop.create_connection
ConnectionRefusedError: [Errno 61] Connection refused

The above exception was the direct cause of the following exception:

Traceback (most recent call last):
  File "/Users/temanmarket/.pyenv/versions/3.9.7/lib/python3.9/site-packages/rasa/core/actions/action.py", line 780, in run
    response: Any = await self.action_endpoint.request(
  File "/Users/temanmarket/.pyenv/versions/3.9.7/lib/python3.9/site-packages/rasa/utils/endpoints.py", line 174, in request
    async with session.request(
  File "/Users/temanmarket/.pyenv/versions/3.9.7/lib/python3.9/site-packages/aiohttp/client.py", line 1197, in __aenter__
    self._resp = await self._coro
  File "/Users/temanmarket/.pyenv/versions/3.9.7/lib/python3.9/site-packages/aiohttp/client.py", line 581, in _request
    conn = await self._connector.connect(
  File "/Users/temanmarket/.pyenv/versions/3.9.7/lib/python3.9/site-packages/aiohttp/connector.py", line 544, in connect
    proto = await self._create_connection(req, traces, timeout)
  File "/Users/temanmarket/.pyenv/versions/3.9.7/lib/python3.9/site-packages/aiohttp/connector.py", line 944, in _create_connection
    _, proto = await self._create_direct_connection(req, traces, timeout)
  File "/Users/temanmarket/.pyenv/versions/3.9.7/lib/python3.9/site-packages/aiohttp/connector.py", line 1257, in _create_direct_connection
    raise last_exc
  File "/Users/temanmarket/.pyenv/versions/3.9.7/lib/python3.9/site-packages/aiohttp/connector.py", line 1226, in _create_direct_connection
    transp, proto = await self._wrap_create_connection(
  File "/Users/temanmarket/.pyenv/versions/3.9.7/lib/python3.9/site-packages/aiohttp/connector.py", line 1033, in _wrap_create_connection
    raise client_error(req.connection_key, exc) from exc
aiohttp.client_exceptions.ClientConnectorError: Cannot connect to host localhost:5055 ssl:default [Connection refused]

During handling of the above exception, another exception occurred:

Traceback (most recent call last):
  File "/Users/temanmarket/.pyenv/versions/3.9.7/lib/python3.9/site-packages/rasa/core/processor.py", line 982, in _run_action
    events = await action.run(
  File "/Users/temanmarket/.pyenv/versions/3.9.7/lib/python3.9/site-packages/rasa/core/actions/action.py", line 821, in run
    raise RasaException(
rasa.shared.exceptions.RasaException: Failed to execute custom action 'action_handle_chatbot'. Couldn't connect to the server at 'http://localhost:5055/webhook.
[93mNo chat connector configured, falling back to the REST input channel. To connect your bot to another channel, read the docs here: https://rasa.com/docs/rasa/messaging-and-voice-channels[0m
